Workbook

Sheet README
A1: ⚠ SIMULATED FINANCIAL INFORMATION - synthetic demonstration accounts of a fictional auto care group, not actual company records. Synthetic data generated for a VisiVault Analytics proof of concept (seed 20240103). Fictional auto care group.
A2: Prairie Auto Care Group (fictional) - Integrated Three-Statement Financial Model
A3: Developed by VisiVault Analytics Ltd. | October 2026
A5: WHAT THIS IS
A6: SIMULATED accounts of a FICTIONAL multi-location Calgary collision & car care group, built by double entry from synthetic operational data.
A7: Synthetic demonstration data. Not actual Ultimate Car Care Group records. Jan-2024 to Sep-2026 are simulated actuals; Oct-2026 to Sep-2027 are FORECASTS.
A9: HOW TO USE
A10: 1. Assumptions!C4 - choose Conservative / Base / Optimistic / Custom (edit the Custom column freely: efficiency, parts cost, cycle time, volume, margin,
A11: collection delays, extra technicians, service-line expansion, opex, prime rate).
A12: 2. Drivers - edit any blue monthly input (demand and technician capacity in billed hours, staffing plan, leases, opex, capex, loan schedule).
A13: 3. Forecast - three statements recalculate; the CHECKS rows and the Checks sheet must stay at 0 / TRUE.
A14: 4. Scenario_Results - stored comparison of the three scenarios and the sensitivity cases.
... A30: Assumptions | Drivers | Forecast | Scenario_Results | Checks | Hist_IS | Hist_BS | Hist_CF | Hist_Balances

Sheet Assumptions
A1: ⚠ SIMULATED FINANCIAL INFORMATION - synthetic demonstration accounts of a fictional auto care group, not actual company records. Synthetic data generated for a VisiVault Analytics proof of concept (seed 20240103). Fictional auto care group.
A2: Forecast assumptions - choose a scenario, or edit the Custom column
A3: Blue cells on yellow are inputs. Column H (Active) feeds every forecast formula.
B4: Active scenario >> | C4: Base
A7: Key | B7: Scenario driver | C7: Unit | D7: Conservative | E7: Base | F7: Optimistic | G7: Custom | H7: Active
A8: eff_change | B8: Technician efficiency change | C8: % | D8: -0.03 | E8: 0 | F8: 0.05 | G8: 0 | H8: =INDEX(D8:G8,MATCH($C$4,$D$7:$G$7,0)) -> 0
A9: parts_cost_change | B9: Parts procurement cost change | C9: % | D9: 0.03 | E9: 0 | F9: -0.02 | G9: 0 | H9: =INDEX(D9:G9,MATCH($C$4,$D$7:$G$7,0)) -> 0
A10: cycle_change | B10: Repair cycle-time change | C10: % | D10: 0 | E10: 0 | F10: -0.1 | G10: 0 | H10: =INDEX(D10:G10,MATCH($C$4,$D$7:$G$7,0)) -> 0
A11: appt_change | B11: Appointment volume change | C11: % | D11: -0.06 | E11: 0 | F11: 0.05 | G11: 0 | H11: =INDEX(D11:G11,MATCH($C$4,$D$7:$G$7,0)) -> 0
A12: margin_change | B12: Gross-margin improvement (relative) | C12: % | D12: 0 | E12: 0 | F12: 0 | G12: 0 | H12: =INDEX(D12:G12,MATCH($C$4,$D$7:$G$7,0)) -> 0
A13: collect_change | B13: Receivable collection-delay change | C13: % | D13: 0.15 | E13: 0 | F13: -0.1 | G13: 0 | H13: =INDEX(D13:G13,MATCH($C$4,$D$7:$G$7,0)) -> 0
A14: hires | B14: Additional collision technicians (from Dec-2026) | C14: # | D14: 0 | E14: 0 | F14: 0 | G14: 0 | H14: =INDEX(D14:G14,MATCH($C$4,$D$7:$G$7,0)) -> 0
A15: expansion | B15: Detailing & paint-protection expansion | C15: % | D15: 0 | E15: 0 | F15: 0.1 | G15: 0 | H15: =INDEX(D15:G15,MATCH($C$4,$D$7:$G$7,0)) -> 0
A16: opex_change | B16: Controllable operating-expense change | C16: % | D16: 0.02 | E16: 0 | F16: 0 | G16: 0 | H16: =INDEX(D16:G16,MATCH($C$4,$D$7:$G$7,0)) -> 0
A17: rate_change | B17: Prime-rate change | C17: % | D17: 0.005 | E17: 0 | F17: 0 | G17: 0 | H17: =INDEX(D17:G17,MATCH($C$4,$D$7:$G$7,0)) -> 0
B19: Scenario notes
B20: Conservative | C20: Demand -6%, technician efficiency -3%, parts cost +3%, collections 15% slower, opex +2%, prime +50 bps.
B21: Base | C21: Model forecasts of demand and technician capacity, TTM rates and cost ratios, current staffing plan and leases, prime flat.
B22: Optimistic | C22: Demand +5%, efficiency +5%, parts cost -2%, cycle time -10%, collections 10% faster, detailing & protection +10%.
A24: Key | B24: Calibrated / policy parameter (TTM Oct-2025 to Sep-2026 unless stated) | H24: Value
A25: rph_coll | B25: Collision revenue per billed body & paint hour (incl. parts, materials, sublet) | H25: 348.97632
A26: rph_mech | B26: Mechanical revenue per billed mechanical hour | H26: 376.78664
A27: parts_coll | B27: Parts cost / collision revenue | H27: 0.39767955
A28: parts_mech | B28: Parts cost / mechanical revenue | H28: 0.34233577
A29: parts_oth | B29: Parts cost / detailing, glass & other revenue | H29: 0.20953297
A30: mat_coll | B30: Paint & materials cost / collision revenue | H30: 0.035391845
A31: mat_oth | B31: Materials cost / detailing & other revenue | H31: 0.042028689
A32: sublet_coll | B32: Sublet cost / collision revenue | H32: 0.014779682
A33: sublet_mech | B33: Sublet cost / mechanical revenue | H33: 0.012420553
A34: adj_rate | B34: Discounts, short-pays & adjustments / service revenue | H34: 0.0073502577
A35: warranty_ratio | B35: Warranty rework parts & sublet / net revenue | H35: 0.00089998412
A36: eff_coll_ttm | B36: eff_coll_ttm | H36: 1.1369002
... A69: sbd_limit | B69: Small-business limit | H69: 500000

Sheet Drivers
A1: ⚠ SIMULATED FINANCIAL INFORMATION - synthetic demonstration accounts of a fictional auto care group, not actual company records. Synthetic data generated for a VisiVault Analytics proof of concept (seed 20240103). Fictional auto care group.
A2: Monthly drivers (inputs) - demand & capacity from the predictive models, staffing plan, leases, opex plan, capex plan, loan schedule
A3: Edit any blue cell; the forecast recalculates. Column C = actual 30-Sep-2026 position (not used by drivers).
A5: Key | B5: Line | C5: Sep-2026 actual | D5: Oct-2026 | E5: Nov-2026 | F5: Dec-2026 | G5: Jan-2027 | H5: Feb-2027 | I5: Mar-2027 | J5: Apr-2027 | K5: May-2027 | L5: Jun-2027 | M5: Jul-2027 | N5: Aug-2027 | O5: Sep-2027 | P5: 12-month total
A6: dem_coll_base | B6: Collision demand - billed body & paint hours (Model 2 RO-volume forecast x hours per RO) | D6: 2285.6 | E6: 2714 | F6: 2288.9 | G6: 2199.2 | H6: 2254.1 | I6: 2082 | J6: 2057.9 | K6: 1678.7 | L6: 2059.2 | M6: 1983.4 | N6: 2130.1 | O6: 1718
A7: dem_mech_base | B7: Mechanical demand - billed hours (Model 2) | D7: 1278.0768 | E7: 1093.5014 | F7: 640.81542 | G7: 770.30167 | H7: 759.74213 | I7: 719.22129 | J7: 955.6846 | K7: 1092.5229 | L7: 780.84289 | M7: 700.79849 | N7: 700.32618 | O7: 733.43261
A8: cap_coll_base | B8: Collision technician capacity - billed hours (Model 5 x efficiency) | D8: 2713.7915 | E8: 2648.6804 | F8: 2372.2778 | G8: 2621.7278 | H8: 2478.8523 | I8: 2836.5126 | J8: 2912.53 | K8: 2601.6664 | L8: 2836.811 | M8: 2289.0523 | N8: 2475.4212 | O8: 2756.6342
A9: cap_mech_base | B9: Mechanical technician capacity - billed hours (Model 5 x efficiency) | D9: 1408.5736 | E9: 1361.8048 | F9: 1260.7605 | G9: 1366.2447 | H9: 1300.8407 | I9: 1467.7622 | J9: 1511.0391 | K9: 1343.141 | L9: 1472.8829 | M9: 1129.4398 | N9: 1315.9957 | O9: 1429.8814
A10: rev_detail_base | B10: Detailing revenue (Model 1) | D10: 49818.876 | E10: 28914.678 | F10: 28623.463 | G10: 31386.088 | H10: 26212.376 | I10: 42310.946 | J10: 60392.943 | K10: 65411.937 | L10: 72507.922 | M10: 59629.453 | N10: 62989.913 | O10: 53724.191
A11: rev_glass_base | B11: Glass revenue (Model 1) | D11: 53335.919 | E11: 50974.559 | F11: 36004.832 | G11: 52279.429 | H11: 46466.136 | I11: 68420.978 | J11: 69253.866 | K11: 76289.37 | L11: 61685.239 | M11: 56157.116 | N11: 73282.19 | O11: 47150.977
A12: rev_other_base | B12: Other services revenue (Model 1) | D12: 44844.94 | E12: 38056.74 | F12: 22726.79 | G12: 46911.53 | H12: 29218.25 | I12: 62981.53 | J12: 77274.89 | K12: 54051.37 | L12: 86525.79 | M12: 141310.65 | N12: 74340.63 | O12: 90328.55
A13: payroll_tech_base | B13: Technician payroll - staffing plan, regular & paid-absence hours (TTM same month +3%) | D13: 257413.38 | E13: 223478.67 | F13: 257413.38 | G13: 265534.83 | H13: 244269.22 | I13: 282315.27 | J13: 269633.25 | K13: 257892.31 | L13: 290733.37 | M13: 290733.37 | N13: 278383.11 | O13: 277668.71
A14: staff_d | B14: Staff compensation plan | D14: 141220.64 | E14: 141220.64 | F14: 141220.64 | G14: 145457.26 | H14: 145457.26 | I14: 145457.26 | J14: 145457.26 | K14: 145457.26 | L14: 145457.26 | M14: 145457.26 | N14: 145457.26 | O14: 145457.26
A15: occupancy_d | B15: Occupancy: lease schedule (+3% Jan) + utilities seasonal | D15: 99702.616 | E15: 104967.14 | F15: 105416.81 | G15: 108921.59 | H15: 108259.45 | I15: 108749.05 | J15: 102371.76 | K15: 102558.95 | L15: 102699.74 | M15: 102658.64 | N15: 102532.77 | O15: 102666.49
A16: marketing_d | B16: Marketing plan | D16: 10799.995 | E16: 10686.671 | F16: 10359.285 | G16: 9703.962 | H16: 10590.864 | I16: 9425.0902 | J16: 9514.583 | K16: 9872.882 | L16: 11208.488 | M16: 10787.961 | N16: 9762.9507 | O16: 9637.7162
A17: ga_d | B17: General & administrative | D17: 30221.992 | E17: 30354.647 | F17: 29455.302 | G17: 34314.663 | H17: 30551.427 | I17: 31001.279 | J17: 31503.816 | K17: 30906.815 | L17: 31134.754 | M17: 30587.087 | N17: 31276.491 | O17: 30287.151
... A30: q_start | B30: Flag: first month of quarter | D30: 1 | E30: 0 | F30: 0 | G30: 1 | H30: 0 | I30: 0 | J30: 1 | K30: 0 | L30: 0 | M30: 1 | N30: 0 | O30: 0

Sheet Forecast
A1: ⚠ SIMULATED FINANCIAL INFORMATION - synthetic demonstration accounts of a fictional auto care group, not actual company records. Synthetic data generated for a VisiVault Analytics proof of concept (seed 20240103). Fictional auto care group.
A2: Integrated 12-month forecast Oct-2026 to Sep-2027 (FORECAST - not historical fact)
A3: Every cell in columns D:O is a formula driven by Assumptions (active scenario) and Drivers. Column C links to the historical ledger.
A5: Key | B5: Line | C5: Sep-2026 actual | D5: Oct-2026 | E5: Nov-2026 | F5: Dec-2026 | G5: Jan-2027 | H5: Feb-2027 | I5: Mar-2027 | J5: Apr-2027 | K5: May-2027 | L5: Jun-2027 | M5: Jul-2027 | N5: Aug-2027 | O5: Sep-2027 | P5: 12-month total
A7: INCOME STATEMENT (forecast)
A8: rev_collision | B8: Collision repair revenue | D8: =D93*Assumptions!$H$25 -> 1041753.9 | E8: =E93*Assumptions!$H$25 -> 1016759.4 | F8: =F93*Assumptions!$H$25 -> 856631.52 | G8: =G93*Assumptions!$H$25 -> 767468.73 | H8: =H93*Assumptions!$H$25 -> 786627.53 | I8: =I93*Assumptions!$H$25 -> 726568.7 | J8: =J93*Assumptions!$H$25 -> 718158.37 | K8: =K93*Assumptions!$H$25 -> 585826.55 | ... O8: =O93*Assumptions!$H$25 -> 599541.32 | P8: =SUM(D8:O8) -> 9253462.1
A9: rev_mech | B9: Mechanical service revenue | D9: =D100*Assumptions!$H$26 -> 517506.29 | E9: =E100*Assumptions!$H$26 -> 412016.71 | F9: =F100*Assumptions!$H$26 -> 241450.68 | G9: =G100*Assumptions!$H$26 -> 290239.38 | H9: =H100*Assumptions!$H$26 -> 286260.68 | I9: =I100*Assumptions!$H$26 -> 270992.97 | J9: =J100*Assumptions!$H$26 -> 360089.19 | K9: =K100*Assumptions!$H$26 -> 411648.02 | ... O9: =O100*Assumptions!$H$26 -> 276347.61 | P9: =SUM(D9:O9) -> 3888687.7
A10: rev_detail | B10: Detailing revenue | D10: =Drivers!D10*(1+Assumptions!$H$11)*(1+Assumptions!$H$15) -> 49818.876 | E10: =Drivers!E10*(1+Assumptions!$H$11)*(1+Assumptions!$H$15) -> 28914.678 | F10: =Drivers!F10*(1+Assumptions!$H$11)*(1+Assumptions!$H$15) -> 28623.463 | G10: =Drivers!G10*(1+Assumptions!$H$11)*(1+Assumptions!$H$15) -> 31386.088 | H10: =Drivers!H10*(1+Assumptions!$H$11)*(1+Assumptions!$H$15) -> 26212.376 | I10: =Drivers!I10*(1+Assumptions!$H$11)*(1+Assumptions!$H$15) -> 42310.946 | J10: =Drivers!J10*(1+Assumptions!$H$11)*(1+Assumptions!$H$15) -> 60392.943 | K10: =Drivers!K10*(1+Assumptions!$H$11)*(1+Assumptions!$H$15) -> 65411.937 | ... O10: =Drivers!O10*(1+Assumptions!$H$11)*(1+Assumptions!$H$15) -> 53724.191 | P10: =SUM(D10:O10) -> 581922.79
A11: rev_glass | B11: Glass repair revenue | D11: =Drivers!D11*(1+Assumptions!$H$11) -> 53335.919 | E11: =Drivers!E11*(1+Assumptions!$H$11) -> 50974.559 | F11: =Drivers!F11*(1+Assumptions!$H$11) -> 36004.832 | G11: =Drivers!G11*(1+Assumptions!$H$11) -> 52279.429 | H11: =Drivers!H11*(1+Assumptions!$H$11) -> 46466.136 | I11: =Drivers!I11*(1+Assumptions!$H$11) -> 68420.978 | J11: =Drivers!J11*(1+Assumptions!$H$11) -> 69253.866 | K11: =Drivers!K11*(1+Assumptions!$H$11) -> 76289.37 | ... O11: =Drivers!O11*(1+Assumptions!$H$11) -> 47150.977 | P11: =SUM(D11:O11) -> 691300.61
A12: rev_other | B12: Other service revenue (PDR, paint protection, ADAS, fees) | D12: =Drivers!D12*(1+Assumptions!$H$11)*(1+Assumptions!$H$15) -> 44844.94 | E12: =Drivers!E12*(1+Assumptions!$H$11)*(1+Assumptions!$H$15) -> 38056.74 | F12: =Drivers!F12*(1+Assumptions!$H$11)*(1+Assumptions!$H$15) -> 22726.79 | G12: =Drivers!G12*(1+Assumptions!$H$11)*(1+Assumptions!$H$15) -> 46911.53 | H12: =Drivers!H12*(1+Assumptions!$H$11)*(1+Assumptions!$H$15) -> 29218.25 | I12: =Drivers!I12*(1+Assumptions!$H$11)*(1+Assumptions!$H$15) -> 62981.53 | J12: =Drivers!J12*(1+Assumptions!$H$11)*(1+Assumptions!$H$15) -> 77274.89 | K12: =Drivers!K12*(1+Assumptions!$H$11)*(1+Assumptions!$H$15) -> 54051.37 | ... O12: =Drivers!O12*(1+Assumptions!$H$11)*(1+Assumptions!$H$15) -> 90328.55 | P12: =SUM(D12:O12) -> 768571.66
A13: gross_rev | B13: Service revenue | D13: =D8+D9+D10+D11+D12 -> 1707259.9 | E13: =E8+E9+E10+E11+E12 -> 1546722.1 | F13: =F8+F9+F10+F11+F12 -> 1185437.3 | G13: =G8+G9+G10+G11+G12 -> 1188285.1 | H13: =H8+H9+H10+H11+H12 -> 1174785 | I13: =I8+I9+I10+I11+I12 -> 1171275.1 | J13: =J8+J9+J10+J11+J12 -> 1285169.3 | K13: =K8+K9+K10+K11+K12 -> 1193227.2 | ... O13: =O8+O9+O10+O11+O12 -> 1067092.6 | P13: =SUM(D13:O13) -> 15183945
A14: adjustments | B14: Less: discounts, insurer short-pays & adjustments | D14: =-Assumptions!$H$34*D13 -> -12548.8 | E14: =-Assumptions!$H$34*E13 -> -11368.806 | F14: =-Assumptions!$H$34*F13 -> -8713.2696 | G14: =-Assumptions!$H$34*G13 -> -8734.2021 | H14: =-Assumptions!$H$34*H13 -> -8634.9723 | I14: =-Assumptions!$H$34*I13 -> -8609.174 | J14: =-Assumptions!$H$34*J13 -> -9446.3252 | K14: =-Assumptions!$H$34*K13 -> -8770.5277 | ... O14: =-Assumptions!$H$34*O13 -> -7843.4059 | P14: =SUM(D14:O14) -> -111605.91
A15: net_rev | B15: Total net revenue | D15: =D13+D14 -> 1694711.1 | E15: =E13+E14 -> 1535353.3 | F15: =F13+F14 -> 1176724 | G15: =G13+G14 -> 1179550.9 | H15: =H13+H14 -> 1166150 | I15: =I13+I14 -> 1162666 | J15: =J13+J14 -> 1275722.9 | K15: =K13+K14 -> 1184456.7 | ... O15: =O13+O14 -> 1059249.2 | P15: =SUM(D15:O15) -> 15072339
A16: labour | B16: Technician labour (staffing plan + overtime + hires) | D16: =-(Drivers!D13+Assumptions!$H$14*Drivers!D26*Assumptions!$H$43+D94*Assumptions!$H$38+D101*Assumptions!$H$39+Assumptions!$H$15*(Drivers!D10+Drivers!D12)*Assumptions!$H$44) -> -273753.94 | E16: =-(Drivers!E13+Assumptions!$H$14*Drivers!E26*Assumptions!$H$43+E94*Assumptions!$H$38+E101*Assumptions!$H$39+Assumptions!$H$15*(Drivers!E10+Drivers!E12)*Assumptions!$H$44) -> -239427.17 | F16: =-(Drivers!F13+Assumptions!$H$14*Drivers!F26*Assumptions!$H$43+F94*Assumptions!$H$38+F101*Assumptions!$H$39+Assumptions!$H$15*(Drivers!F10+Drivers!F12)*Assumptions!$H$44) -> -262376.16 | G16: =-(Drivers!G13+Assumptions!$H$14*Drivers!G26*Assumptions!$H$43+G94*Assumptions!$H$38+G101*Assumptions!$H$39+Assumptions!$H$15*(Drivers!G10+Drivers!G12)*Assumptions!$H$44) -> -265534.83 | H16: =-(Drivers!H13+Assumptions!$H$14*Drivers!H26*Assumptions!$H$43+H94*Assumptions!$H$38+H101*Assumptions!$H$39+Assumptions!$H$15*(Drivers!H10+Drivers!H12)*Assumptions!$H$44) -> -244269.22 | I16: =-(Drivers!I13+Assumptions!$H$14*Drivers!I26*Assumptions!$H$43+I94*Assumptions!$H$38+I101*Assumptions!$H$39+Assumptions!$H$15*(Drivers!I10+Drivers!I12)*Assumptions!$H$44) -> -282315.27 | J16: =-(Drivers!J13+Assumptions!$H$14*Drivers!J26*Assumptions!$H$43+J94*Assumptions!$H$38+J101*Assumptions!$H$39+Assumptions!$H$15*(Drivers!J10+Drivers!J12)*Assumptions!$H$44) -> -269633.25 | K16: =-(Drivers!K13+Assumptions!$H$14*Drivers!K26*Assumptions!$H$43+K94*Assumptions!$H$38+K101*Assumptions!$H$39+Assumptions!$H$15*(Drivers!K10+Drivers!K12)*Assumptions!$H$44) -> -257892.31 | ... O16: =-(Drivers!O13+Assumptions!$H$14*Drivers!O26*Assumptions!$H$43+O94*Assumptions!$H$38+O101*Assumptions!$H$39+Assumptions!$H$15*(Drivers!O10+Drivers!O12)*Assumptions!$H$44) -> -277668.71 | P16: =SUM(D16:O16) -> -3232720.7
A17: parts | B17: Parts | D17: =-(D8*Assumptions!$H$27+D9*Assumptions!$H$28+(D10+D11+D12)*Assumptions!$H$29)*(1+Assumptions!$H$9) -> -622455.95 | E17: =-(E8*Assumptions!$H$27+E9*Assumptions!$H$28+(E10+E11+E12)*Assumptions!$H$29)*(1+Assumptions!$H$9) -> -570106.06 | F17: =-(F8*Assumptions!$H$27+F9*Assumptions!$H$28+(F10+F11+F12)*Assumptions!$H$29)*(1+Assumptions!$H$9) -> -441625.82 | G17: =-(G8*Assumptions!$H$27+G9*Assumptions!$H$28+(G10+G11+G12)*Assumptions!$H$29)*(1+Assumptions!$H$9) -> -431926.14 | H17: =-(H8*Assumptions!$H$27+H9*Assumptions!$H$28+(H10+H11+H12)*Assumptions!$H$29)*(1+Assumptions!$H$9) -> -432173.69 | I17: =-(I8*Assumptions!$H$27+I9*Assumptions!$H$28+(I10+I11+I12)*Assumptions!$H$29)*(1+Assumptions!$H$9) -> -418110.8 | J17: =-(J8*Assumptions!$H$27+J9*Assumptions!$H$28+(J10+J11+J12)*Assumptions!$H$29)*(1+Assumptions!$H$9) -> -452225.23 | K17: =-(K8*Assumptions!$H$27+K9*Assumptions!$H$28+(K10+K11+K12)*Assumptions!$H$29)*(1+Assumptions!$H$9) -> -414909.72 | ... O17: =-(O8*Assumptions!$H$27+O9*Assumptions!$H$28+(O10+O11+O12)*Assumptions!$H$29)*(1+Assumptions!$H$9) -> -373092.48 | P17: =SUM(D17:O17) -> -5438973
A18: materials | B18: Paint & materials | D18: =-(D8*Assumptions!$H$30+(D10+D12)*Assumptions!$H$31) -> -40848.187 | E18: =-(E8*Assumptions!$H$30+(E10+E12)*Assumptions!$H$31) -> -38799.713 | F18: =-(F8*Assumptions!$H$30+(F10+F12)*Assumptions!$H$31) -> -32475.954 | G18: =-(G8*Assumptions!$H$30+(G10+G12)*Assumptions!$H$31) -> -30452.88 | H18: =-(H8*Assumptions!$H$30+(H10+H12)*Assumptions!$H$31) -> -30169.876 | I18: =-(I8*Assumptions!$H$30+(I10+I12)*Assumptions!$H$31) -> -30139.911 | J18: =-(J8*Assumptions!$H$30+(J10+J12)*Assumptions!$H$31) -> -31202.948 | K18: =-(K8*Assumptions!$H$30+(K10+K12)*Assumptions!$H$31) -> -25754.368 | ... O18: =-(O8*Assumptions!$H$30+(O10+O12)*Assumptions!$H$31) -> -27273.221 | P18: =SUM(D18:O18) -> -384256.61
A19: sublet | B19: Subcontractor costs (sublet repairs & towing) | D19: =-(D8*Assumptions!$H$32+D9*Assumptions!$H$33) -> -21824.505 | E19: =-(E8*Assumptions!$H$32+E9*Assumptions!$H$33) -> -20144.856 | F19: =-(F8*Assumptions!$H$32+F9*Assumptions!$H$33) -> -15659.692 | G19: =-(G8*Assumptions!$H$32+G9*Assumptions!$H$33) -> -14947.877 | H19: =-(H8*Assumptions!$H$32+H9*Assumptions!$H$33) -> -15181.621 | I19: =-(I8*Assumptions!$H$32+I9*Assumptions!$H$33) -> -14104.337 | J19: =-(J8*Assumptions!$H$32+J9*Assumptions!$H$33) -> -15086.659 | K19: =-(K8*Assumptions!$H$32+K9*Assumptions!$H$33) -> -13771.226 | ... O19: =-(O8*Assumptions!$H$32+O9*Assumptions!$H$33) -> -12293.42 | P19: =SUM(D19:O19) -> -185062.88
A20: warranty | B20: Warranty rework - parts & sublet | D20: =-Assumptions!$H$35*D15 -> -1525.2131 | E20: =-Assumptions!$H$35*E15 -> -1381.7936 | F20: =-Assumptions!$H$35*F15 -> -1059.0329 | G20: =-Assumptions!$H$35*G15 -> -1061.5771 | H20: =-Assumptions!$H$35*H15 -> -1049.5165 | I20: =-Assumptions!$H$35*I15 -> -1046.3809 | J20: =-Assumptions!$H$35*J15 -> -1148.1304 | K20: =-Assumptions!$H$35*K15 -> -1065.9922 | ... O20: =-Assumptions!$H$35*O15 -> -953.3075 | P20: =SUM(D20:O20) -> -13564.866
A21: margin_uplift | B21: Gross-margin initiatives (scenario) | D21: =Assumptions!$H$12*(D15+D16+D17+D18+D19+D20) -> 0 | E21: =Assumptions!$H$12*(E15+E16+E17+E18+E19+E20) -> 0 | F21: =Assumptions!$H$12*(F15+F16+F17+F18+F19+F20) -> 0 | G21: =Assumptions!$H$12*(G15+G16+G17+G18+G19+G20) -> 0 | H21: =Assumptions!$H$12*(H15+H16+H17+H18+H19+H20) -> 0 | I21: =Assumptions!$H$12*(I15+I16+I17+I18+I19+I20) -> 0 | J21: =Assumptions!$H$12*(J15+J16+J17+J18+J19+J20) -> 0 | K21: =Assumptions!$H$12*(K15+K16+K17+K18+K19+K20) -> 0 | ... O21: =Assumptions!$H$12*(O15+O16+O17+O18+O19+O20) -> 0 | P21: =SUM(D21:O21) -> 0
A22: cogs | B22: Cost of sales | D22: =D16+D17+D18+D19+D20+D21 -> -960407.79 | E22: =E16+E17+E18+E19+E20+E21 -> -869859.59 | F22: =F16+F17+F18+F19+F20+F21 -> -753196.66 | G22: =G16+G17+G18+G19+G20+G21 -> -743923.3 | H22: =H16+H17+H18+H19+H20+H21 -> -722843.92 | I22: =I16+I17+I18+I19+I20+I21 -> -745716.7 | J22: =J16+J17+J18+J19+J20+J21 -> -769296.22 | K22: =K16+K17+K18+K19+K20+K21 -> -713393.62 | ... O22: =O16+O17+O18+O19+O20+O21 -> -691281.14 | P22: =SUM(D22:O22) -> -9254578
A23: gross_profit | B23: Gross profit | D23: =D15+D22 -> 734303.3 | E23: =E15+E22 -> 665493.72 | F23: =F15+F22 -> 423527.37 | G23: =G15+G22 -> 435627.65 | H23: =H15+H22 -> 443306.08 | I23: =I15+I22 -> 416949.25 | J23: =J15+J22 -> 506426.71 | K23: =K15+K22 -> 471063.09 | ... O23: =O15+O22 -> 367968.1 | P23: =SUM(D23:O23) -> 5817761
A24: staff | B24: Staff compensation | D24: =-Drivers!D14*(1+Assumptions!$H$16) -> -141220.64 | E24: =-Drivers!E14*(1+Assumptions!$H$16) -> -141220.64 | F24: =-Drivers!F14*(1+Assumptions!$H$16) -> -141220.64 | G24: =-Drivers!G14*(1+Assumptions!$H$16) -> -145457.26 | H24: =-Drivers!H14*(1+Assumptions!$H$16) -> -145457.26 | I24: =-Drivers!I14*(1+Assumptions!$H$16) -> -145457.26 | J24: =-Drivers!J14*(1+Assumptions!$H$16) -> -145457.26 | K24: =-Drivers!K14*(1+Assumptions!$H$16) -> -145457.26 | ... O24: =-Drivers!O14*(1+Assumptions!$H$16) -> -145457.26 | P24: =SUM(D24:O24) -> -1732777.3
A25: occupancy | B25: Occupancy (lease schedule, utilities) | D25: =-Drivers!D15 -> -99702.616 | E25: =-Drivers!E15 -> -104967.14 | F25: =-Drivers!F15 -> -105416.81 | G25: =-Drivers!G15 -> -108921.59 | H25: =-Drivers!H15 -> -108259.45 | I25: =-Drivers!I15 -> -108749.05 | J25: =-Drivers!J15 -> -102371.76 | K25: =-Drivers!K15 -> -102558.95 | ... O25: =-Drivers!O15 -> -102666.49 | P25: =SUM(D25:O25) -> -1251505
A26: marketing | B26: Marketing & advertising | D26: =-Drivers!D16*(1+Assumptions!$H$16) -> -10799.995 | E26: =-Drivers!E16*(1+Assumptions!$H$16) -> -10686.671 | F26: =-Drivers!F16*(1+Assumptions!$H$16) -> -10359.285 | G26: =-Drivers!G16*(1+Assumptions!$H$16) -> -9703.962 | H26: =-Drivers!H16*(1+Assumptions!$H$16) -> -10590.864 | I26: =-Drivers!I16*(1+Assumptions!$H$16) -> -9425.0902 | J26: =-Drivers!J16*(1+Assumptions!$H$16) -> -9514.583 | K26: =-Drivers!K16*(1+Assumptions!$H$16) -> -9872.882 | ... O26: =-Drivers!O16*(1+Assumptions!$H$16) -> -9637.7162 | P26: =SUM(D26:O26) -> -122350.45
A27: g_and_a | B27: General & administrative | D27: =-Drivers!D17*(1+Assumptions!$H$16) -> -30221.992 | E27: =-Drivers!E17*(1+Assumptions!$H$16) -> -30354.647 | F27: =-Drivers!F17*(1+Assumptions!$H$16) -> -29455.302 | G27: =-Drivers!G17*(1+Assumptions!$H$16) -> -34314.663 | H27: =-Drivers!H17*(1+Assumptions!$H$16) -> -30551.427 | I27: =-Drivers!I17*(1+Assumptions!$H$16) -> -31001.279 | J27: =-Drivers!J17*(1+Assumptions!$H$16) -> -31503.816 | K27: =-Drivers!K17*(1+Assumptions!$H$16) -> -30906.815 | ... O27: =-Drivers!O17*(1+Assumptions!$H$16) -> -30287.151 | P27: =SUM(D27:O27) -> -371595.42
A28: shop_ops | B28: Shop operations (incl. card fees) | D28: =-(Drivers!D18*(1+Assumptions!$H$16)+Assumptions!$H$45*D15) -> -53114.385 | E28: =-(Drivers!E18*(1+Assumptions!$H$16)+Assumptions!$H$45*E15) -> -51090.601 | F28: =-(Drivers!F18*(1+Assumptions!$H$16)+Assumptions!$H$45*F15) -> -48794.453 | G28: =-(Drivers!G18*(1+Assumptions!$H$16)+Assumptions!$H$45*G15) -> -50157.112 | H28: =-(Drivers!H18*(1+Assumptions!$H$16)+Assumptions!$H$45*H15) -> -47126.035 | I28: =-(Drivers!I18*(1+Assumptions!$H$16)+Assumptions!$H$45*I15) -> -49567.947 | J28: =-(Drivers!J18*(1+Assumptions!$H$16)+Assumptions!$H$45*J15) -> -51884.54 | K28: =-(Drivers!K18*(1+Assumptions!$H$16)+Assumptions!$H$45*K15) -> -52234.681 | ... O28: =-(Drivers!O18*(1+Assumptions!$H$16)+Assumptions!$H$45*O15) -> -50411.012 | P28: =SUM(D28:O28) -> -605881.96
A29: opex | B29: Operating expenses (before depreciation) | D29: =D24+D25+D26+D27+D28 -> -335059.63 | E29: =E24+E25+E26+E27+E28 -> -338319.7 | F29: =F24+F25+F26+F27+F28 -> -335246.49 | G29: =G24+G25+G26+G27+G28 -> -348554.58 | H29: =H24+H25+H26+H27+H28 -> -341985.03 | I29: =I24+I25+I26+I27+I28 -> -344200.62 | J29: =J24+J25+J26+J27+J28 -> -340731.95 | K29: =K24+K25+K26+K27+K28 -> -341030.59 | ... O29: =O24+O25+O26+O27+O28 -> -338459.63 | P29: =SUM(D29:O29) -> -4084110.1
A30: ebitda | B30: EBITDA | D30: =D23+D29 -> 399243.67 | E30: =E23+E29 -> 327174.02 | F30: =F23+F29 -> 88280.875 | G30: =G23+G29 -> 87073.067 | H30: =H23+H29 -> 101321.04 | I30: =I23+I29 -> 72748.629 | J30: =J23+J29 -> 165694.76 | K30: =K23+K29 -> 130032.51 | ... O30: =O23+O29 -> 29508.467 | P30: =SUM(D30:O30) -> 1733650.9
A31: da | B31: Depreciation | D31: =-(Drivers!D23+C106/Assumptions!$H$66) -> -23245.84 | E31: =-(Drivers!E23+D106/Assumptions!$H$66) -> -23245.84 | F31: =-(Drivers!F23+E106/Assumptions!$H$66) -> -23245.84 | G31: =-(Drivers!G23+F106/Assumptions!$H$66) -> -23245.84 | H31: =-(Drivers!H23+G106/Assumptions!$H$66) -> -23245.84 | I31: =-(Drivers!I23+H106/Assumptions!$H$66) -> -23245.84 | J31: =-(Drivers!J23+I106/Assumptions!$H$66) -> -22162.71 | K31: =-(Drivers!K23+J106/Assumptions!$H$66) -> -22162.51 | ... O31: =-(Drivers!O23+N106/Assumptions!$H$66) -> -22162.51 | P31: =SUM(D31:O31) -> -272450.3
A32: ebit | B32: Operating income (EBIT) | D32: =D30+D31 -> 375997.83 | E32: =E30+E31 -> 303928.18 | F32: =F30+F31 -> 65035.035 | G32: =G30+G31 -> 63827.227 | H32: =H30+H31 -> 78075.204 | I32: =I30+I31 -> 49502.789 | J32: =J30+J31 -> 143532.05 | K32: =K30+K31 -> 107870 | ... O32: =O30+O31 -> 7345.9566 | P32: =SUM(D32:O32) -> 1461200.6
A33: interest | B33: Interest expense | D33: =-(C111*(Assumptions!$H$56+Assumptions!$H$17+Assumptions!$H$57)+C56*(Assumptions!$H$56+Assumptions!$H$17+Assumptions!$H$58))/12 -> -2464.2187 | E33: =-(D111*(Assumptions!$H$56+Assumptions!$H$17+Assumptions!$H$57)+D56*(Assumptions!$H$56+Assumptions!$H$17+Assumptions!$H$58))/12 -> -2374.4853 | F33: =-(E111*(Assumptions!$H$56+Assumptions!$H$17+Assumptions!$H$57)+E56*(Assumptions!$H$56+Assumptions!$H$17+Assumptions!$H$58))/12 -> -2284.7518 | G33: =-(F111*(Assumptions!$H$56+Assumptions!$H$17+Assumptions!$H$57)+F56*(Assumptions!$H$56+Assumptions!$H$17+Assumptions!$H$58))/12 -> -2195.0184 | H33: =-(G111*(Assumptions!$H$56+Assumptions!$H$17+Assumptions!$H$57)+G56*(Assumptions!$H$56+Assumptions!$H$17+Assumptions!$H$58))/12 -> -2105.2849 | I33: =-(H111*(Assumptions!$H$56+Assumptions!$H$17+Assumptions!$H$57)+H56*(Assumptions!$H$56+Assumptions!$H$17+Assumptions!$H$58))/12 -> -2015.5515 | J33: =-(I111*(Assumptions!$H$56+Assumptions!$H$17+Assumptions!$H$57)+I56*(Assumptions!$H$56+Assumptions!$H$17+Assumptions!$H$58))/12 -> -1925.818 | K33: =-(J111*(Assumptions!$H$56+Assumptions!$H$17+Assumptions!$H$57)+J56*(Assumptions!$H$56+Assumptions!$H$17+Assumptions!$H$58))/12 -> -1836.0846 | ... O33: =-(N111*(Assumptions!$H$56+Assumptions!$H$17+Assumptions!$H$57)+N56*(Assumptions!$H$56+Assumptions!$H$17+Assumptions!$H$58))/12 -> -1477.1507 | P33: =SUM(D33:O33) -> -23648.217
A34: pbt | B34: Income before tax | D34: =D32+D33 -> 373533.61 | E34: =E32+E33 -> 301553.69 | F34: =F32+F33 -> 62750.284 | G34: =G32+G33 -> 61632.209 | H34: =H32+H33 -> 75969.919 | I34: =I32+I33 -> 47487.238 | J34: =J32+J33 -> 141606.23 | K34: =K32+K33 -> 106033.91 | ... O34: =O32+O33 -> 5868.8059 | P34: =SUM(D34:O34) -> 1437552.4
A35: tax | B35: Income taxes | D35: =-(D116-IF(Drivers!D27,0,C116)) -> -85912.734 | E35: =-(E116-IF(Drivers!E27,0,D116)) -> -69357.349 | F35: =-(F116-IF(Drivers!F27,0,E116)) -> -14432.565 | G35: =-(G116-IF(Drivers!G27,0,F116)) -> -6779.543 | H35: =-(H116-IF(Drivers!H27,0,G116)) -> -8356.6911 | I35: =-(I116-IF(Drivers!I27,0,H116)) -> -5223.5961 | J35: =-(J116-IF(Drivers!J27,0,I116)) -> -15576.685 | K35: =-(K116-IF(Drivers!K27,0,J116)) -> -11663.73 | ... O35: =-(O116-IF(Drivers!O27,0,N116)) -> -1349.8254 | P35: =SUM(D35:O35) -> -270637.05
A36: net_income | B36: Net income | D36: =D34+D35 -> 287620.88 | E36: =E34+E35 -> 232196.34 | F36: =F34+F35 -> 48317.718 | G36: =G34+G35 -> 54852.666 | H36: =H34+H35 -> 67613.228 | I36: =I34+I35 -> 42263.641 | J36: =J34+J35 -> 126029.54 | K36: =K34+K35 -> 94370.182 | ... O36: =O34+O35 -> 4518.9805 | P36: =SUM(D36:O36) -> 1166915.3
A38: BALANCE SHEET (forecast; column C = actual 30-Sep-2026 from the general ledger)
A39: cash | B39: Cash | C39: =Hist_Balances!$AJ$6 -> 1390234 | D39: =C39+D82 -> 1736043.9 | E39: =D39+E82 -> 2045166.7 | F39: =E39+F82 -> 1758471.1 | G39: =F39+G82 -> 1693642.9 | H39: =G39+H82 -> 1809259 | I39: =H39+I82 -> 1536640.5 | J39: =I39+J82 -> 1608448.1 | K39: =J39+K82 -> 1760135.9 | ... O39: =N39+O82 -> 2160422.3
A40: ar_insurer | B40: Insurer receivables | C40: =Hist_Balances!$AJ$8 -> 573560.54 | D40: =Assumptions!$H$47*(1+Assumptions!$H$13)/30.4*Assumptions!$H$46*D15*(1+Assumptions!$H$55) -> 860622.84 | E40: =Assumptions!$H$47*(1+Assumptions!$H$13)/30.4*Assumptions!$H$46*E15*(1+Assumptions!$H$55) -> 779696.39 | F40: =Assumptions!$H$47*(1+Assumptions!$H$13)/30.4*Assumptions!$H$46*F15*(1+Assumptions!$H$55) -> 597574.17 | G40: =Assumptions!$H$47*(1+Assumptions!$H$13)/30.4*Assumptions!$H$46*G15*(1+Assumptions!$H$55) -> 599009.76 | H40: =Assumptions!$H$47*(1+Assumptions!$H$13)/30.4*Assumptions!$H$46*H15*(1+Assumptions!$H$55) -> 592204.38 | I40: =Assumptions!$H$47*(1+Assumptions!$H$13)/30.4*Assumptions!$H$46*I15*(1+Assumptions!$H$55) -> 590435.08 | J40: =Assumptions!$H$47*(1+Assumptions!$H$13)/30.4*Assumptions!$H$46*J15*(1+Assumptions!$H$55) -> 647848.65 | K40: =Assumptions!$H$47*(1+Assumptions!$H$13)/30.4*Assumptions!$H$46*K15*(1+Assumptions!$H$55) -> 601501.05 | ... O40: =Assumptions!$H$47*(1+Assumptions!$H$13)/30.4*Assumptions!$H$46*O15*(1+Assumptions!$H$55) -> 537917.11
A41: ar_other | B41: Card settlements & fleet receivables | C41: =Hist_Balances!$AJ$7+Hist_Balances!$AJ$9 -> 110132.82 | D41: =Assumptions!$H$48*(1+Assumptions!$H$13)*D15*(1+Assumptions!$H$55) -> 120331.44 | E41: =Assumptions!$H$48*(1+Assumptions!$H$13)*E15*(1+Assumptions!$H$55) -> 109016.38 | F41: =Assumptions!$H$48*(1+Assumptions!$H$13)*F15*(1+Assumptions!$H$55) -> 83552.229 | G41: =Assumptions!$H$48*(1+Assumptions!$H$13)*G15*(1+Assumptions!$H$55) -> 83752.953 | H41: =Assumptions!$H$48*(1+Assumptions!$H$13)*H15*(1+Assumptions!$H$55) -> 82801.43 | I41: =Assumptions!$H$48*(1+Assumptions!$H$13)*I15*(1+Assumptions!$H$55) -> 82554.049 | J41: =Assumptions!$H$48*(1+Assumptions!$H$13)*J15*(1+Assumptions!$H$55) -> 90581.558 | K41: =Assumptions!$H$48*(1+Assumptions!$H$13)*K15*(1+Assumptions!$H$55) -> 84101.282 | ... O41: =Assumptions!$H$48*(1+Assumptions!$H$13)*O15*(1+Assumptions!$H$55) -> 75211.038
A42: inventory | B42: Parts inventory | C42: =Hist_Balances!$AJ$10+Hist_Balances!$AJ$11 -> 126398.77 | D42: =-Assumptions!$H$49*D17 -> 206785.21 | E42: =-Assumptions!$H$49*E17 -> 189394.13 | F42: =-Assumptions!$H$49*F17 -> 146711.89 | G42: =-Assumptions!$H$49*G17 -> 143489.57 | H42: =-Assumptions!$H$49*H17 -> 143571.81 | I42: =-Assumptions!$H$49*I17 -> 138900 | J42: =-Assumptions!$H$49*J17 -> 150233.1 | K42: =-Assumptions!$H$49*K17 -> 137836.57 | ... O42: =-Assumptions!$H$49*O17 -> 123944.52
A43: materials_inv | B43: Paint & detailing materials | C43: =Hist_Balances!$AJ$12 -> 11736.47 | D43: =-Assumptions!$H$50*D18 -> 17319.317 | E43: =-Assumptions!$H$50*E18 -> 16450.78 | F43: =-Assumptions!$H$50*F18 -> 13769.555 | G43: =-Assumptions!$H$50*G18 -> 12911.787 | H43: =-Assumptions!$H$50*H18 -> 12791.796 | I43: =-Assumptions!$H$50*I18 -> 12779.091 | J43: =-Assumptions!$H$50*J18 -> 13229.81 | K43: =-Assumptions!$H$50*K18 -> 10919.654 | ... O43: =-Assumptions!$H$50*O18 -> 11563.636
...

Sheet Scenario_Results
A1: ⚠ SIMULATED FINANCIAL INFORMATION - synthetic demonstration accounts of a fictional auto care group, not actual company records. Synthetic data generated for a VisiVault Analytics proof of concept (seed 20240103). Fictional auto care group.
A2: Scenario comparison and sensitivity analysis (values computed by the Python engine at build time)
A3: The Forecast sheet recalculates live for the scenario selected on Assumptions; this sheet stores all three for comparison.
B5: Conservative | C5: Base | D5: Optimistic
A6: net_revenue | B6: 14201963 | C6: 15072339 | D6: 15957254
A7: gross_profit | B7: 5144721.9 | C7: 5817761 | D7: 6460218.4
A8: gross_margin_pct | B8: 36.225429 | C8: 38.598926 | D8: 40.484524
A9: ebitda | B9: 1012373.9 | C9: 1733650.9 | D9: 2369754.2
A10: operating_profit | B10: 739923.6 | C10: 1461200.6 | D10: 2097303.9
A11: net_income | B11: 570260.75 | C11: 1166915.3 | D11: 1656714.9
A12: net_margin_pct | B12: 4.0153658 | C12: 7.7420984 | D12: 10.382205
A13: cfo | B13: 794257.23 | C13: 1536188.3 | D13: 2188678
A14: closing_cash | B14: 1477491.2 | C14: 2160422.3 | D14: 2760912
A15: min_cash | B15: 1205281.4 | C15: 1536640.5 | D15: 1821336.8
A16: peak_revolver | B16: 0 | C16: 0 | D16: 0
A17: closing_working_capital | B17: 1421109.8 | C17: 1958764.3 | D17: 2396563.9
... A26: max_abs_cash_check | B26: 1.1641532e-10 | C26: 1.1641532e-10 | D26: 2.0372681e-10
A29: Sensitivity analysis (one driver at a time vs Base)
A30: scenario | B30: driver | C30: value | D30: delta_net_revenue | E30: delta_gross_profit | F30: delta_operating_profit | G30: delta_net_income | H30: delta_cfo | I30: delta_closing_cash | J30: delta_working_capital | K30: delta_collision_hours | L30: delta_overtime_hours | M30: net_income | N30: closing_cash
A31: 10% improvement in technician efficiency | B31: eff_change | C31: 0.1 | D31: 24236.79 | E31: 34191.407 | F31: 34017.375 | G31: 26193.379 | H31: 26193.379 | I31: 16193.379 | J31: 16193.379 | K31: 69.965364 | L31: -347.28838 | M31: 1193108.7 | N31: 2176615.7
A32: 5% reduction in parts procurement costs | B32: parts_cost_change | C32: -0.05 | D32: 0 | E32: 271948.65 | F32: 271948.65 | G32: 209400.46 | H32: 248015.45 | I32: 223015.45 | J32: 184400.46 | K32: 0 | L32: 0 | M32: 1376315.8 | N32: 2383437.7
A33: 15% reduction in average repair cycle time | B33: cycle_change | C33: -0.15 | D33: 13745.84 | E33: 5395.2444 | F33: 5296.543 | G33: 4078.3381 | H33: 22407.744 | I33: 20407.744 | J33: 2078.3381 | K33: 36.954268 | L33: 36.954268 | M33: 1170993.7 | N33: 2180830
A34: 10% increase in appointment volume | B34: appt_change | C34: 0.1 | D34: 1406285.1 | E34: 822291.12 | F34: 812193.35 | G34: 625388.88 | H34: 754274.96 | I34: 720274.96 | J34: 591388.88 | K34: 2370.4885 | L34: 352.27835 | M34: 1792304.2 | N34: 2880697.3
A35: 5% improvement in gross margin | B35: margin_change | C35: 0.05 | D35: 0 | E35: 290888.05 | F35: 290888.05 | G35: 223983.8 | H35: 273172.06 | I35: 245172.06 | J35: 195983.8 | K35: 0 | L35: 0 | M35: 1390899.1 | N35: 2405594.4
A36: 20% reduction in receivables collection delays | B36: collect_change | C36: -0.2 | D36: 0 | E36: 0 | F36: 0 | G36: 0 | H36: 122625.63 | I36: 122625.63 | J36: 0 | K36: 0 | L36: 0 | M36: 1166915.3 | N36: 2283047.9
A37: Hire 2 additional collision technicians | B37: hires | C37: 2 | D37: 0 | E37: -148342.9 | F37: -148342.9 | G37: -114224.03 | H37: -141002.97 | I37: -138002.97 | J37: -111224.03 | K37: 0 | L37: -82.420342 | M37: 1052691.3 | N37: 2022419.3
A38: 25% expansion of detailing & paint protection | B38: expansion | C38: 0.25 | D38: 335141.99 | E38: 189770.37 | F38: 187363.89 | G38: 144270.2 | H38: 170876.16 | I38: 161876.16 | J38: 135270.2 | K38: 0 | L38: 0 | M38: 1311185.5 | N38: 2322298.5
A39: Operating expenses -5% | B39: opex_change | C39: -0.05 | D39: 0 | E39: 0 | F39: 136218.94 | G39: 104888.58 | H39: 124913.2 | I39: 114913.2 | J39: 94888.584 | K39: 0 | L39: 0 | M39: 1271803.9 | N39: 2275335.5
A40: Prime rate +100 bps | B40: rate_change | C40: 0.01 | D40: 0 | E40: 0 | F40: 0 | G40: -2747.9375 | H40: -3321.5 | I40: -3321.5 | J40: -2747.9375 | K40: 0 | L40: 0 | M40: 1164167.4 | N40: 2157100.8
A43: LIVE: active scenario (formulas on the Forecast sheet)
A44: Net revenue | B44: =SUM(Forecast!D15:O15) -> 15072339
A45: Net income | B45: =SUM(Forecast!D36:O36) -> 1166915.3
A46: Closing cash Sep-2027 | B46: =Forecast!O39 -> 2160422.3
A47: Minimum month-end cash | B47: =MIN(Forecast!D39:O39) -> 1536640.5
A48: Peak revolver | B48: =MAX(0,MAX(Forecast!D56:O56)) -> 0
A49: Insurer receivables Sep-2027 | B49: =Forecast!O40 -> 537917.11
A50: Max |balance-sheet check| | B50: =MAX(ABS(MIN(Forecast!D85:O85)),ABS(MAX(Forecast!D85:O85))) -> 0

Sheet Checks
A1: ⚠ SIMULATED FINANCIAL INFORMATION - synthetic demonstration accounts of a fictional auto care group, not actual company records. Synthetic data generated for a VisiVault Analytics proof of concept (seed 20240103). Fictional auto care group.
A2: Model integrity checks (live formulas - every value must be 0 / TRUE)
A5: Check | B5: Value | C5: Pass?
A6: Trial balance: max |sum of account balances| (Dec-2023 to Sep-2026) | B6: =MAX(ABS(MIN(Hist_Balances!$C$64:$AJ$64)),ABS(MAX(Hist_Balances!$C$64:$AJ$64))) -> 0 | C6: =ABS(B6)<0.01 -> TRUE
A7: Historical balance sheet: max |assets - liabilities - equity| | B7: =MAX(ABS(MIN(Hist_BS!C33:AI33)),ABS(MAX(Hist_BS!C33:AI33))) -> 0 | C7: =ABS(B7)<0.01 -> TRUE
A8: Historical cash flow: max |closing cash - balance-sheet cash| | B8: =MAX(ABS(MIN(Hist_CF!C24:AI24)),ABS(MAX(Hist_CF!C24:AI24))) -> 0 | C8: =ABS(B8)<0.01 -> TRUE
A9: Forecast balance sheet: max |assets - liabilities - equity| | B9: =MAX(ABS(MIN(Forecast!D85:O85)),ABS(MAX(Forecast!D85:O85))) -> 0 | C9: =ABS(B9)<0.01 -> TRUE
A10: Forecast cash flow: max |closing cash - balance-sheet cash| | B10: =MAX(ABS(MIN(Forecast!D86:O86)),ABS(MAX(Forecast!D86:O86))) -> 1.6007107e-10 | C10: =ABS(B10)<0.01 -> TRUE
A11: Forecast opening cash = historical closing cash (Sep-2026) | B11: =ROUND(Forecast!C39-Hist_BS!AI6,2) -> 0 | C11: =ABS(B11)<0.01 -> TRUE
A12: ALL CHECKS PASS | C12: =AND(C6:C11) -> TRUE

Sheet Hist_IS
A1: ⚠ SIMULATED FINANCIAL INFORMATION - synthetic demonstration accounts of a fictional auto care group, not actual company records. Synthetic data generated for a VisiVault Analytics proof of concept (seed 20240103). Fictional auto care group.
A2: Historical income statements - consolidated, interbranch eliminated (CAD)
A3: Monthly values from the general ledger; subtotal rows are live formulas. FY columns sum the months.
A5: Line | B5: Key | C5: 2024-01 | D5: 2024-02 | E5: 2024-03 | F5: 2024-04 | G5: 2024-05 | H5: 2024-06 | I5: 2024-07 | J5: 2024-08 | K5: 2024-09 | L5: 2024-10 | M5: 2024-11 | N5: 2024-12 | O5: 2025-01 | P5: 2025-02 | Q5: 2025-03 | R5: 2025-04 | S5: 2025-05 | T5: 2025-06 | U5: 2025-07 | V5: 2025-08 | W5: 2025-09 | X5: 2025-10 | Y5: 2025-11 | Z5: 2025-12 | AA5: 2026-01 | AB5: 2026-02 | AC5: 2026-03 | AD5: 2026-04 | AE5: 2026-05 | AF5: 2026-06 | AG5: 2026-07 | AH5: 2026-08 | AI5: 2026-09 | AJ5: FY2024 | AK5: FY2025 | AL5: YTD Sep-2026
A6: Collision repair revenue | B6: rev_collision | C6: 535748.84 | D6: 697212.33 | E6: 600100.5 | F6: 635993.75 | G6: 641852.68 | H6: 385344.1 | I6: 381913.17 | J6: 416953.28 | K6: 646361.59 | L6: 538820.54 | M6: 576821.13 | N6: 532711.48 | O6: 699721.5 | P6: 617088.75 | Q6: 648451.89 | R6: 499351.84 | S6: 668416.45 | T6: 548686.8 | U6: 624666.58 | V6: 765727.54 | W6: 657986.31 | X6: 657157.08 | Y6: 563695.48 | Z6: 729662.15 | AA6: 1115733.1 | AB6: 831639.92 | AC6: 819803.78 | AD6: 796755.85 | AE6: 628523.38 | AF6: 643079.8 | AG6: 674357.74 | AH6: 757456.93 | AI6: 667874.6 | AJ6: =SUM(C6:N6) -> 6589833.4 | AK6: =SUM(O6:Z6) -> 7680612.4 | AL6: =SUM(AA6:AI6) -> 6935225.1
A7: Mechanical service revenue | B7: rev_mech | C7: 185909.12 | D7: 187246.52 | E7: 154214.04 | F7: 266248.4 | G7: 313601.58 | H7: 208274.83 | I7: 169098 | J7: 178348.41 | K7: 190058.5 | L7: 369088.9 | M7: 347868.64 | N7: 171743.08 | O7: 186033.77 | P7: 218788.91 | Q7: 203322.18 | R7: 260923.49 | S7: 343077.28 | T7: 228817.78 | U7: 224374.52 | V7: 214544.27 | W7: 213509.76 | X7: 405072.41 | Y7: 440663.15 | Z7: 215245.71 | AA7: 270709.69 | AB7: 213835.05 | AC7: 238018.94 | AD7: 383098.24 | AE7: 439580.36 | AF7: 311008.96 | AG7: 236370.23 | AH7: 248304.35 | AI7: 260873.48 | AJ7: =SUM(C7:N7) -> 2741700 | AK7: =SUM(O7:Z7) -> 3154373.2 | AL7: =SUM(AA7:AI7) -> 2601799.3
A8: Detailing revenue | B8: rev_detail | C8: 6032.6 | D8: 5684.6 | E8: 12470 | F8: 15892.8 | G8: 13975 | H8: 15239.2 | I8: 16348.6 | J8: 19350 | K8: 10939.2 | L8: 13192.4 | M8: 9262.2 | N8: 7817.4 | O8: 10414.8 | P8: 7272 | Q8: 10368 | R8: 17118 | S8: 30357 | T8: 37665 | U8: 34749 | V8: 30798 | W8: 36225 | X8: 33669 | Y8: 17604 | Z8: 22329 | AA8: 22839.8 | AB8: 24195.6 | AC8: 38295.6 | AD8: 61513.6 | AE8: 57659.6 | AF8: 66204.2 | AG8: 42121.4 | AH8: 53335.6 | AI8: 55826.6 | AJ8: =SUM(C8:N8) -> 146204 | AK8: =SUM(O8:Z8) -> 288568.8 | AL8: =SUM(AA8:AI8) -> 421992
A9: Glass repair revenue | B9: rev_glass | C9: 36990.19 | D9: 28679.49 | E9: 37116.23 | F9: 49812.14 | G9: 46379.55 | H9: 37325.37 | I9: 36745.57 | J9: 39138.71 | K9: 25593.51 | L9: 38664.88 | M9: 33297.28 | N9: 20253.07 | O9: 34216.23 | P9: 29155.72 | Q9: 54639.62 | R9: 40927.86 | S9: 58813.24 | T9: 46501.84 | U9: 36182.69 | V9: 50513.56 | W9: 27530.72 | X9: 37789.39 | Y9: 39084.16 | Z9: 31715.35 | AA9: 37113.25 | AB9: 38630.76 | AC9: 50478.39 | AD9: 52260.8 | AE9: 52842.69 | AF9: 44753.98 | AG9: 45201.94 | AH9: 69551.56 | AI9: 53702.35 | AJ9: =SUM(C9:N9) -> 429995.99 | AK9: =SUM(O9:Z9) -> 487070.38 | AL9: =SUM(AA9:AI9) -> 444535.72
A10: Other service revenue (PDR, paint protection, ADAS, fees) | B10: rev_other | C10: 8595.16 | D10: 6625.65 | E10: 9074.35 | F10: 8669 | G10: 9262.97 | H10: 8337.47 | I10: 7424.71 | J10: 48418.62 | K10: 17771.2 | L10: 12649.76 | M10: 9651.44 | N10: 10124.96 | O10: 9919.63 | P10: 9412.9 | Q10: 12579.49 | R10: 8922.78 | S10: 18835.23 | T10: 30291.58 | U10: 56356.25 | V10: 80300.51 | W10: 54704.21 | X10: 44844.94 | Y10: 38056.74 | Z10: 22726.79 | AA10: 46911.53 | AB10: 29218.25 | AC10: 62981.53 | AD10: 77274.89 | AE10: 54051.37 | AF10: 86525.79 | AG10: 141310.65 | AH10: 74340.63 | AI10: 90328.55 | AJ10: =SUM(C10:N10) -> 156605.29 | AK10: =SUM(O10:Z10) -> 386951.05 | AL10: =SUM(AA10:AI10) -> 662943.19
A11: Service revenue | B11: gross_rev | C11: =C6+C7+C8+C9+C10 -> 773275.91 | D11: =D6+D7+D8+D9+D10 -> 925448.59 | E11: =E6+E7+E8+E9+E10 -> 812975.12 | F11: =F6+F7+F8+F9+F10 -> 976616.09 | G11: =G6+G7+G8+G9+G10 -> 1025071.8 | H11: =H6+H7+H8+H9+H10 -> 654520.97 | I11: =I6+I7+I8+I9+I10 -> 611530.05 | J11: =J6+J7+J8+J9+J10 -> 702209.02 | ... AI11: =AI6+AI7+AI8+AI9+AI10 -> 1128605.6 | AJ11: =SUM(C11:N11) -> 10064339 | AK11: =SUM(O11:Z11) -> 11997576 | AL11: =SUM(AA11:AI11) -> 11066495
A12: Less: discounts, insurer short-pays & adjustments | B12: adjustments | C12: -3112.93 | D12: -4732.89 | E12: -4456.2 | F12: -5368.98 | G12: -5214.14 | H12: -3730.93 | I12: -3919.31 | J12: -7050.52 | K12: -6318.43 | L12: -4659.09 | M12: -5848.26 | N12: -7455.76 | O12: -7003.99 | P12: -5728.49 | Q12: -3822.35 | R12: -7025.26 | S12: -5024.58 | T12: -6709.7 | U12: -9388.76 | V12: -8121.62 | W12: -6005.21 | X12: -5200.75 | Y12: -5837.75 | Z12: -6626.11 | AA12: -15377.53 | AB12: -10945.71 | AC12: -7126.27 | AD12: -10302.45 | AE12: -7986.27 | AF12: -9013.52 | AG12: -8618.73 | AH12: -9706.23 | AI12: -8851.09 | AJ12: =SUM(C12:N12) -> -61867.44 | AK12: =SUM(O12:Z12) -> -76494.57 | AL12: =SUM(AA12:AI12) -> -87927.8
A13: Total net revenue | B13: net_rev | C13: =C11+C12 -> 770162.98 | D13: =D11+D12 -> 920715.7 | E13: =E11+E12 -> 808518.92 | F13: =F11+F12 -> 971247.11 | G13: =G11+G12 -> 1019857.6 | H13: =H11+H12 -> 650790.04 | I13: =I11+I12 -> 607610.74 | J13: =J11+J12 -> 695158.5 | ... AI13: =AI11+AI12 -> 1119754.5 | AJ13: =SUM(C13:N13) -> 10002471 | AK13: =SUM(O13:Z13) -> 11921081 | AL13: =SUM(AA13:AI13) -> 10978567
A14: Technician labour (wages, overtime & burden) | B14: labour | C14: -184665.84 | D14: -193295.91 | E14: -189178.51 | F14: -192140.21 | G14: -209583.72 | H14: -175669.4 | I14: -186308.75 | J14: -198237.28 | K14: -194715.88 | L14: -200562.87 | M14: -186447.4 | N14: -194208.37 | O14: -217523.26 | P14: -189598.76 | Q14: -213934.54 | R14: -200480.19 | S14: -262485.37 | T14: -246148.51 | U14: -274533.12 | V14: -276595.87 | W14: -265937.89 | X14: -274955.86 | Y14: -226633.95 | Z14: -273070.77 | AA14: -305536.52 | AB14: -264113.63 | AC14: -295322.5 | AD14: -281149.44 | AE14: -257540.24 | AF14: -294083.74 | AG14: -301668.59 | AH14: -292708.23 | AI14: -286020.55 | AJ14: =SUM(C14:N14) -> -2305014.1 | AK14: =SUM(O14:Z14) -> -2921898.1 | AL14: =SUM(AA14:AI14) -> -2578143.4
A15: Parts | B15: parts | C15: -293335.48 | D15: -333201.91 | E15: -295964.87 | F15: -373933.87 | G15: -392874.2 | H15: -232476.47 | I15: -209669.54 | J15: -228318.21 | K15: -327203.6 | L15: -381127.7 | M15: -373425.05 | N15: -277633.97 | O15: -334414.74 | P15: -314303.88 | Q15: -333132.75 | R15: -305328.15 | S15: -421390.49 | T15: -313567.03 | U15: -340506.54 | V15: -405551.86 | W15: -326934.78 | X15: -426972.28 | Y15: -434859.06 | Z15: -375548.4 | AA15: -560347.42 | AB15: -416923.86 | AC15: -416408.5 | AD15: -482027.65 | AE15: -467364.96 | AF15: -387410.92 | AG15: -370202.35 | AH15: -422239.01 | AI15: -377243.98 | AJ15: =SUM(C15:N15) -> -3719164.9 | AK15: =SUM(O15:Z15) -> -4332510 | AL15: =SUM(AA15:AI15) -> -3900168.6
A16: Paint & materials | B16: materials | C16: -19001.18 | D16: -25231.99 | E16: -21877.97 | F16: -23054.44 | G16: -23723.59 | H16: -14315.13 | I16: -15493.63 | J16: -17347.33 | K16: -24263.19 | L16: -20136.71 | M16: -21273.3 | N16: -19183.82 | O16: -27463.93 | P16: -23067.3 | Q16: -23952.09 | R16: -19269.34 | S16: -25390.7 | T16: -22742.32 | U16: -25635.19 | V16: -30607.72 | W16: -28328.72 | X16: -27421.32 | Y16: -20905.01 | Z16: -27047.79 | AA16: -40205.08 | AB16: -31989.93 | AC16: -34295.56 | AD16: -35082.49 | AE16: -25670.69 | AF16: -30151.59 | AG16: -30673.75 | AH16: -32071.04 | AI16: -30132.79 | AJ16: =SUM(C16:N16) -> -244902.28 | AK16: =SUM(O16:Z16) -> -301831.43 | AL16: =SUM(AA16:AI16) -> -290272.92
A17: Subcontractor costs (sublet repairs & towing) | B17: sublet | C17: -10636.54 | D17: -14436.04 | E17: -13037.97 | F17: -17280.48 | G17: -8712.2 | H17: -10328.04 | I17: -6089.55 | J17: -5076.08 | K17: -14997.07 | L17: -8279.17 | M17: -12930.21 | N17: -10563.67 | O17: -11604.39 | P17: -13501.79 | Q17: -11984.87 | R17: -9745.36 | S17: -19672.16 | T17: -15315.44 | U17: -10252.04 | V17: -11636 | W17: -14623.88 | X17: -16300.7 | Y17: -13427.54 | Z17: -16128.47 | AA17: -22299.46 | AB17: -15159.68 | AC17: -11174.66 | AD17: -12871.67 | AE17: -16060.85 | AF17: -11717.72 | AG17: -11469.74 | AH17: -11797.8 | AI17: -17473.1 | AJ17: =SUM(C17:N17) -> -132367.02 | AK17: =SUM(O17:Z17) -> -164192.64 | AL17: =SUM(AA17:AI17) -> -130024.68
A18: Warranty rework - parts & sublet | B18: warranty | C18: -522.03 | D18: -1923.35 | E18: -516.97 | F18: -466.67 | G18: -528.6 | H18: -44.57 | I18: -1205.22 | J18: -683.08 | K18: -887.68 | L18: -390.72 | M18: 0 | N18: -935.89 | O18: -792.55 | P18: -67.6 | Q18: -733.77 | R18: -255.74 | S18: -2163.01 | T18: 0 | U18: -18.42 | V18: -1428.25 | W18: -280.71 | X18: -826.23 | Y18: -504.32 | Z18: -519.24 | AA18: -1237.06 | AB18: -1283.49 | AC18: -516.41 | AD18: -561.99 | AE18: -339.28 | AF18: -258.18 | AG18: -1883.26 | AH18: -2815.51 | AI18: -1731.77 | AJ18: =SUM(C18:N18) -> -8104.78 | AK18: =SUM(O18:Z18) -> -7589.84 | AL18: =SUM(AA18:AI18) -> -10626.95
A19: Inventory adjustments & obsolescence | B19: inv_adj | C19: 0 | D19: 0 | E19: -298.1 | F19: 0 | G19: 0 | H19: 17.75 | I19: 0 | J19: 0 | K19: -303.34 | L19: 0 | M19: 0 | N19: -186.37 | O19: 0 | P19: 0 | Q19: -87.29 | R19: 0 | S19: 0 | T19: -223.77 | U19: 0 | V19: 0 | W19: -9.74 | X19: 0 | Y19: 0 | Z19: 19.04 | AA19: 0 | AB19: 0 | AC19: -201.31 | AD19: 0 | AE19: 0 | AF19: -9.45 | AG19: 0 | AH19: 0 | AI19: -165.51 | AJ19: =SUM(C19:N19) -> -770.06 | AK19: =SUM(O19:Z19) -> -301.76 | AL19: =SUM(AA19:AI19) -> -376.27
A20: Cost of sales | B20: cogs | C20: =C14+C15+C16+C17+C18+C19 -> -508161.07 | D20: =D14+D15+D16+D17+D18+D19 -> -568089.2 | E20: =E14+E15+E16+E17+E18+E19 -> -520874.39 | F20: =F14+F15+F16+F17+F18+F19 -> -606875.67 | G20: =G14+G15+G16+G17+G18+G19 -> -635422.31 | H20: =H14+H15+H16+H17+H18+H19 -> -432815.86 | I20: =I14+I15+I16+I17+I18+I19 -> -418766.69 | J20: =J14+J15+J16+J17+J18+J19 -> -449661.98 | ... AI20: =AI14+AI15+AI16+AI17+AI18+AI19 -> -712767.7 | AJ20: =SUM(C20:N20) -> -6410323.1 | AK20: =SUM(O20:Z20) -> -7728323.7 | AL20: =SUM(AA20:AI20) -> -6909612.9
A21: Gross profit | B21: gross_profit | C21: =C13+C20 -> 262001.91 | D21: =D13+D20 -> 352626.5 | E21: =E13+E20 -> 287644.53 | F21: =F13+F20 -> 364371.44 | G21: =G13+G20 -> 384435.33 | H21: =H13+H20 -> 217974.18 | I21: =I13+I20 -> 188844.05 | J21: =J13+J20 -> 245496.52 | ... AI21: =AI13+AI20 -> 406986.79 | AJ21: =SUM(C21:N21) -> 3592148.1 | AK21: =SUM(O21:Z21) -> 4192757.5 | AL21: =SUM(AA21:AI21) -> 4068954.6
A22: Staff compensation (branch & group) | B22: staff | C22: -100570 | D22: -100570 | E22: -100570 | F22: -100570 | G22: -100570 | H22: -100570 | I22: -100570 | J22: -100570 | K22: -100570 | L22: -100570 | M22: -100570 | N22: -100570 | O22: -109755.77 | P22: -109755.77 | Q22: -109755.77 | R22: -137107.42 | S22: -137107.42 | T22: -137107.42 | U22: -137107.42 | V22: -137107.42 | W22: -137107.42 | X22: -137107.42 | Y22: -137107.42 | Z22: -137107.42 | AA22: -141220.64 | AB22: -141220.64 | AC22: -141220.64 | AD22: -141220.64 | AE22: -141220.64 | AF22: -141220.64 | AG22: -141220.64 | AH22: -141220.64 | AI22: -141220.64 | AJ22: =SUM(C22:N22) -> -1206840 | AK22: =SUM(O22:Z22) -> -1563234.1 | AL22: =SUM(AA22:AI22) -> -1270985.8
A23: Occupancy (rent, CAM & property tax, utilities) | B23: occupancy | C23: -72843.66 | D23: -73435.17 | E23: -73704.37 | F23: -69047.85 | G23: -68945.94 | H23: -68738.92 | I23: -68827.72 | J23: -69209.81 | K23: -69109.39 | L23: -68862.37 | M23: -72766.65 | N23: -73342.49 | O23: -76061.55 | P23: -100421.52 | Q23: -101076.5 | R23: -95896.46 | S23: -97015.31 | T23: -96692.8 | U23: -96861.42 | V23: -97383.11 | W23: -96937.89 | X23: -96839.25 | Y23: -101975.37 | Z23: -102414.07 | AA23: -105820.42 | AB23: -105174.43 | AC23: -105652.09 | AD23: -99430.34 | AE23: -99612.97 | AF23: -99750.33 | AG23: -99710.23 | AH23: -99587.43 | AI23: -99717.89 | AJ23: =SUM(C23:N23) -> -848834.34 | AK23: =SUM(O23:Z23) -> -1159575.3 | AL23: =SUM(AA23:AI23) -> -914456.13
A24: Marketing & advertising | B24: marketing | C24: -10139.31 | D24: -8940.78 | E24: -8972.45 | F24: -10281.34 | G24: -9020.94 | H24: -9624.6 | I24: -9490.67 | J24: -9934.84 | K24: -9218.83 | L24: -8687.15 | M24: -9862.56 | N24: -9694.48 | O24: -9283.52 | P24: -9871.2 | Q24: -10739.22 | R24: -38866.32 | S24: -32504.94 | T24: -10155.81 | U24: -10676.64 | V24: -10246.8 | W24: -10048.28 | X24: -10536.58 | Y24: -10426.02 | Z24: -10106.62 | AA24: -9467.28 | AB24: -10332.55 | AC24: -9195.21 | AD24: -9282.52 | AE24: -9632.08 | AF24: -10935.11 | AG24: -10524.84 | AH24: -9524.83 | AI24: -9402.65 | AJ24: =SUM(C24:N24) -> -113867.95 | AK24: =SUM(O24:Z24) -> -173461.95 | AL24: =SUM(AA24:AI24) -> -88297.07
A25: General & administrative (insurance, professional, software, network, training) | B25: g_and_a | C25: -27452.59 | D25: -24646.12 | E25: -23979.55 | F25: -23522.46 | G25: -23745.35 | H25: -23950.88 | I25: -23433.37 | J25: -23866.01 | K25: -24614.13 | L25: -23605.95 | M25: -24585.99 | N25: -24416.1 | O25: -29447.16 | P25: -25999.34 | Q25: -25396.93 | R25: -25421.6 | S25: -28994.88 | T25: -29574.41 | U25: -29629.88 | V25: -29623.03 | W25: -29163.16 | X25: -29484.87 | Y25: -29614.29 | Z25: -28736.88 | AA25: -33477.72 | AB25: -29806.27 | AC25: -30245.15 | AD25: -30735.43 | AE25: -30152.99 | AF25: -30375.37 | AG25: -29841.06 | AH25: -30513.65 | AI25: -29548.44 | AJ25: =SUM(C25:N25) -> -291818.5 | AK25: =SUM(O25:Z25) -> -341086.43 | AL25: =SUM(AA25:AI25) -> -274696.08
A26: Shop operations (supplies, maintenance, courtesy vehicles, courier & waste, card fees) | B26: shop_ops | C26: -31810.43 | D26: -32712.36 | E26: -32935.65 | F26: -34119.14 | G26: -35071.66 | H26: -33106.69 | I26: -31995.86 | J26: -32743.54 | K26: -33832.07 | L26: -34551.74 | M26: -35944.58 | N26: -33345.47 | O26: -33656.05 | P26: -35056.66 | Q26: -35882.78 | R26: -36866.71 | S26: -47973.67 | T26: -47532.17 | U26: -45477.98 | V26: -48217.42 | W26: -45487.06 | X26: -48531.54 | Y26: -48546.26 | Z26: -45438.64 | AA26: -48446.41 | AB26: -45107.46 | AC26: -48818.61 | AD26: -52696.72 | AE26: -52560.22 | AF26: -48649.58 | AG26: -49827.24 | AH26: -48717.03 | AI26: -50572.91 | AJ26: =SUM(C26:N26) -> -402169.19 | AK26: =SUM(O26:Z26) -> -518666.94 | AL26: =SUM(AA26:AI26) -> -445396.18
A27: Operating expenses (before depreciation) | B27: opex | C27: =C22+C23+C24+C25+C26 -> -242815.99 | D27: =D22+D23+D24+D25+D26 -> -240304.43 | E27: =E22+E23+E24+E25+E26 -> -240162.02 | F27: =F22+F23+F24+F25+F26 -> -237540.79 | G27: =G22+G23+G24+G25+G26 -> -237353.89 | H27: =H22+H23+H24+H25+H26 -> -235991.09 | I27: =I22+I23+I24+I25+I26 -> -234317.62 | J27: =J22+J23+J24+J25+J26 -> -236324.2 | ... AI27: =AI22+AI23+AI24+AI25+AI26 -> -330462.53 | AJ27: =SUM(C27:N27) -> -2863530 | AK27: =SUM(O27:Z27) -> -3756024.7 | AL27: =SUM(AA27:AI27) -> -2993831.2
A28: EBITDA | B28: ebitda | C28: =C21+C27 -> 19185.92 | D28: =D21+D27 -> 112322.07 | E28: =E21+E27 -> 47482.51 | F28: =F21+F27 -> 126830.65 | G28: =G21+G27 -> 147081.44 | H28: =H21+H27 -> -18016.91 | I28: =I21+I27 -> -45473.57 | J28: =J21+J27 -> 9172.32 | ... AI28: =AI21+AI27 -> 76524.26 | AJ28: =SUM(C28:N28) -> 728618.12 | AK28: =SUM(O28:Z28) -> 436732.88 | AL28: =SUM(AA28:AI28) -> 1075123.3
A29: Depreciation | B29: da | C29: -15625 | D29: -15625 | E29: -15625 | F29: -15625 | G29: -15625 | H29: -15625 | I29: -15625 | J29: -15625 | K29: -15625 | L29: -16758.33 | M29: -16758.33 | N29: -16758.33 | O29: -16758.33 | P29: -16758.33 | Q29: -16758.33 | R29: -20175 | S29: -23016.67 | T29: -23016.67 | U29: -23016.67 | V29: -23016.67 | W29: -23016.67 | X29: -22016.67 | Y29: -22016.67 | Z29: -22016.67 | AA29: -22016.67 | AB29: -22016.67 | AC29: -22454.17 | AD29: -22454.17 | AE29: -22454.17 | AF29: -23245.84 | AG29: -23245.84 | AH29: -23245.84 | AI29: -23245.84 | AJ29: =SUM(C29:N29) -> -190899.99 | AK29: =SUM(O29:Z29) -> -251583.35 | AL29: =SUM(AA29:AI29) -> -204379.21
A30: Operating income (EBIT) | B30: ebit | C30: =C28+C29 -> 3560.92 | D30: =D28+D29 -> 96697.07 | E30: =E28+E29 -> 31857.51 | F30: =F28+F29 -> 111205.65 | G30: =G28+G29 -> 131456.44 | H30: =H28+H29 -> -33641.91 | I30: =I28+I29 -> -61098.57 | J30: =J28+J29 -> -6452.68 | ... AI30: =AI28+AI29 -> 53278.42 | AJ30: =SUM(C30:N30) -> 537718.13 | AK30: =SUM(O30:Z30) -> 185149.53 | AL30: =SUM(AA30:AI30) -> 870744.14
A31: Interest expense | B31: interest | C31: -3220 | D31: -3152.92 | E31: -3085.83 | F31: -3018.75 | G31: -2951.67 | H31: -2806.2 | I31: -2664.38 | J31: -2600.94 | K31: -2464.58 | L31: -2260.78 | M31: -2202.81 | N31: -2009.95 | O31: -1890 | P31: -1837.5 | Q31: -4423.02 | R31: -4372.34 | S31: -4276.67 | T31: -4180.99 | U31: -4085.31 | V31: -3989.64 | W31: -3756.98 | X31: -3531.09 | Y31: -3442.19 | Z31: -3353.28 | AA31: -3264.38 | AB31: -3175.47 | AC31: -3086.57 | AD31: -2997.66 | AE31: -2908.76 | AF31: -2819.84 | AG31: -2730.94 | AH31: -2642.03 | AI31: -2553.13 | AJ31: =SUM(C31:N31) -> -32438.81 | AK31: =SUM(O31:Z31) -> -43139.01 | AL31: =SUM(AA31:AI31) -> -26178.78
A32: Income before tax | B32: pbt | C32: =C30+C31 -> 340.92 | D32: =D30+D31 -> 93544.15 | E32: =E30+E31 -> 28771.68 | F32: =F30+F31 -> 108186.9 | G32: =G30+G31 -> 128504.77 | H32: =H30+H31 -> -36448.11 | I32: =I30+I31 -> -63762.95 | J32: =J30+J31 -> -9053.62 | ... AI32: =AI30+AI31 -> 50725.29 | AJ32: =SUM(C32:N32) -> 505279.32 | AK32: =SUM(O32:Z32) -> 142010.52 | AL32: =SUM(AA32:AI32) -> 844565.36
A33: Income taxes | B33: tax | C33: -37.5 | D33: -10289.86 | E33: -3164.88 | F33: -11900.56 | G33: -14135.53 | H33: 4009.3 | I33: 7013.92 | J33: 995.9 | K33: -7326.09 | L33: -11216.03 | M33: -16523.49 | N33: 6360.58 | O33: -7111.58 | P33: -3932.51 | Q33: -4144.91 | R33: 8092.25 | S33: -1373.16 | T33: 6710.44 | U33: 1759.47 | V33: -4784.26 | W33: -254.94 | X33: -8668.91 | Y33: -4818.84 | Z33: 2905.79 | AA33: -20304.98 | AB33: -4429.68 | AC33: -9224.66 | AD33: -20909.93 | AE33: -22662.61 | AF33: -14244.11 | AG33: -13281.29 | AH33: -17525.96 | AI33: -11666.81 | AJ33: =SUM(C33:N33) -> -56214.24 | AK33: =SUM(O33:Z33) -> -15621.16 | AL33: =SUM(AA33:AI33) -> -134250.03
A34: Net income | B34: net_income | C34: =C32+C33 -> 303.42 | D34: =D32+D33 -> 83254.29 | E34: =E32+E33 -> 25606.8 | F34: =F32+F33 -> 96286.34 | G34: =G32+G33 -> 114369.24 | H34: =H32+H33 -> -32438.81 | I34: =I32+I33 -> -56749.03 | J34: =J32+J33 -> -8057.72 | ... AI34: =AI32+AI33 -> 39058.48 | AJ34: =SUM(C34:N34) -> 449065.08 | AK34: =SUM(O34:Z34) -> 126389.36 | AL34: =SUM(AA34:AI34) -> 710315.33

Sheet Hist_BS
A1: ⚠ SIMULATED FINANCIAL INFORMATION - synthetic demonstration accounts of a fictional auto care group, not actual company records. Synthetic data generated for a VisiVault Analytics proof of concept (seed 20240103). Fictional auto care group.
A2: Historical balance sheets - month end (CAD)
A3: Monthly values from the general ledger; subtotal rows are live formulas. FY columns sum the months.
A5: Line | B5: Key | C5: 2024-01 | D5: 2024-02 | E5: 2024-03 | F5: 2024-04 | G5: 2024-05 | H5: 2024-06 | I5: 2024-07 | J5: 2024-08 | K5: 2024-09 | L5: 2024-10 | M5: 2024-11 | N5: 2024-12 | O5: 2025-01 | P5: 2025-02 | Q5: 2025-03 | R5: 2025-04 | S5: 2025-05 | T5: 2025-06 | U5: 2025-07 | V5: 2025-08 | W5: 2025-09 | X5: 2025-10 | Y5: 2025-11 | Z5: 2025-12 | AA5: 2026-01 | AB5: 2026-02 | AC5: 2026-03 | AD5: 2026-04 | AE5: 2026-05 | AF5: 2026-06 | AG5: 2026-07 | AH5: 2026-08 | AI5: 2026-09 | AJ5: FY2024 | AK5: FY2025 | AL5: YTD Sep-2026
A6: Cash | B6: cash | C6: 393720.32 | D6: 372419.59 | E6: 460110.57 | F6: 615172.88 | G6: 789119.67 | H6: 878504.97 | I6: 816261.3 | J6: 739018.59 | K6: 540268.22 | L6: 903226.19 | M6: 1083658.8 | N6: 846954.72 | O6: 691324.08 | P6: 729463.65 | Q6: 772353.79 | R6: 602823.51 | S6: 661000.43 | T6: 628697.79 | U6: 433184.42 | V6: 517582.44 | W6: 493927.6 | X6: 683095.21 | Y6: 864574.46 | Z6: 643396.37 | AA6: 510492.61 | AB6: 633407.78 | AC6: 930312.83 | AD6: 1079663.6 | AE6: 1191103.8 | AF6: 1342769.4 | AG6: 1129346 | AH6: 1300367.5 | AI6: 1390234 | AJ6: =N6 -> 846954.72 | AK6: =Z6 -> 643396.37 | AL6: =AI6 -> 1390234
A7: Insurer receivables (direct billing) | B7: ar_insurer | C7: 433861.48 | D7: 603581.3 | E7: 505108.03 | F7: 496841.21 | G7: 504740 | H7: 344074.43 | I7: 271127.44 | J7: 358310.92 | K7: 622300.62 | L7: 417249.48 | M7: 428467.66 | N7: 363070.71 | O7: 519555.24 | P7: 579289.91 | Q7: 590551.85 | R7: 411207.64 | S7: 501139.62 | T7: 410705.57 | U7: 547488.23 | V7: 616272.2 | W7: 633976.19 | X7: 585491.41 | Y7: 502017.27 | Z7: 515688.02 | AA7: 830843.66 | AB7: 720229.64 | AC7: 545393.95 | AD7: 623573.87 | AE7: 532091.1 | AF7: 468813.23 | AG7: 661457.7 | AH7: 647790.93 | AI7: 573560.54 | AJ7: =N7 -> 363070.71 | AK7: =Z7 -> 515688.02 | AL7: =AI7 -> 573560.54
A8: Card settlements & fleet receivables | B8: ar_other | C8: 76816.1 | D8: 53225.68 | E8: 35753.46 | F8: 76769.76 | G8: 71033.01 | H8: 30226.43 | I8: 61692.04 | J8: 62229.64 | K8: 31874.83 | L8: 62115.75 | M8: 67818.77 | N8: 51204.67 | O8: 61775.66 | P8: 71892 | Q8: 54330.92 | R8: 57030.39 | S8: 55786.75 | T8: 41892.16 | U8: 85027.46 | V8: 53009.85 | W8: 74454.67 | X8: 97419.16 | Y8: 74093.55 | Z8: 46911.99 | AA8: 70021.64 | AB8: 79759.33 | AC8: 104522.65 | AD8: 123012.25 | AE8: 79373.03 | AF8: 90501.98 | AG8: 81619.99 | AH8: 65088.72 | AI8: 110132.82 | AJ8: =N8 -> 51204.67 | AK8: =Z8 -> 46911.99 | AL8: =AI8 -> 110132.82
